Workbook

Sheet Dashboard
B2: MOBILE MANUFACTURING — CONSOLIDATED DASHBOARD
B3: Production • Sales • Revenue • Inventory • Monthly Trends | Live links to analysis sheets — refresh source data and this dashboard updates
B5: TOTAL PRODUCTION | D5: TOTAL SALES | F5: TOTAL REVENUE (LAKHS) | H5: UNSOLD INVENTORY | J5: INVENTORY UTILIZATION | L5: TOTAL BRANDS
B6: ='Production Analysis'!B3 -> 812043 | D6: ='Sales Analysis'!B3 -> 641347 | F6: ='Revenue Analysis'!B3 -> 403008 | H6: ='Inventory Analysis'!I3 -> 170696 | J6: ='Inventory Analysis'!M3 -> 0.78979438 | L6: ='Production Analysis'!D3 -> 5
B9: Avg Production | D9: Avg Sales | F9: Avg Revenue (Lakhs) | H9: Max Production (Model) | J9: Min Production (Model) | L9: Highest Sales (Model) | N9: Lowest Sales (Model)
B10: ='Production Analysis'!F3 -> 2800 | D10: ='Sales Analysis'!D3 -> 2212 | F10: ='Revenue Analysis'!E3 -> 1390 | H10: ='Production Analysis'!H3 -> 4987 | J10: ='Production Analysis'!J3 -> 511 | L10: ='Sales Analysis'!F3 -> 4898 | N10: ='Sales Analysis'!H3 -> 337
B12: Brand-wise Performance
B13: Brand | C13: Production | D13: Sales | E13: Revenue (Lakhs) | F13: Unsold Qty
B14: Apple | C14: =INDEX('Production Analysis'!$B$9:$B$13,MATCH($B14,'Production Analysis'!$A$9:$A$13,0)) -> 162257 | D14: =INDEX('Sales Analysis'!$B$9:$B$13,MATCH($B14,'Sales Analysis'!$A$9:$A$13,0)) -> 130533 | E14: =INDEX('Revenue Analysis'!$D$9:$D$13,MATCH($B14,'Revenue Analysis'!$C$9:$C$13,0)) -> 97452 | F14: =INDEX('Inventory Analysis'!$E$10:$E$14,MATCH($B14,'Inventory Analysis'!$D$10:$D$14,0)) -> 31724
B15: Oneplus | C15: =INDEX('Production Analysis'!$B$9:$B$13,MATCH($B15,'Production Analysis'!$A$9:$A$13,0)) -> 167240 | D15: =INDEX('Sales Analysis'!$B$9:$B$13,MATCH($B15,'Sales Analysis'!$A$9:$A$13,0)) -> 130390 | E15: =INDEX('Revenue Analysis'!$D$9:$D$13,MATCH($B15,'Revenue Analysis'!$C$9:$C$13,0)) -> 81796 | F15: =INDEX('Inventory Analysis'!$E$10:$E$14,MATCH($B15,'Inventory Analysis'!$D$10:$D$14,0)) -> 36850
B16: Samsung | C16: =INDEX('Production Analysis'!$B$9:$B$13,MATCH($B16,'Production Analysis'!$A$9:$A$13,0)) -> 167106 | D16: =INDEX('Sales Analysis'!$B$9:$B$13,MATCH($B16,'Sales Analysis'!$A$9:$A$13,0)) -> 130382 | E16: =INDEX('Revenue Analysis'!$D$9:$D$13,MATCH($B16,'Revenue Analysis'!$C$9:$C$13,0)) -> 85889 | F16: =INDEX('Inventory Analysis'!$E$10:$E$14,MATCH($B16,'Inventory Analysis'!$D$10:$D$14,0)) -> 36724
B17: Vivo | C17: =INDEX('Production Analysis'!$B$9:$B$13,MATCH($B17,'Production Analysis'!$A$9:$A$13,0)) -> 171213 | D17: =INDEX('Sales Analysis'!$B$9:$B$13,MATCH($B17,'Sales Analysis'!$A$9:$A$13,0)) -> 134317 | E17: =INDEX('Revenue Analysis'!$D$9:$D$13,MATCH($B17,'Revenue Analysis'!$C$9:$C$13,0)) -> 91271 | F17: =INDEX('Inventory Analysis'!$E$10:$E$14,MATCH($B17,'Inventory Analysis'!$D$10:$D$14,0)) -> 36896
B18: Xiaomi | C18: =INDEX('Production Analysis'!$B$9:$B$13,MATCH($B18,'Production Analysis'!$A$9:$A$13,0)) -> 144227 | D18: =INDEX('Sales Analysis'!$B$9:$B$13,MATCH($B18,'Sales Analysis'!$A$9:$A$13,0)) -> 115725 | E18: =INDEX('Revenue Analysis'!$D$9:$D$13,MATCH($B18,'Revenue Analysis'!$C$9:$C$13,0)) -> 75077 | F18: =INDEX('Inventory Analysis'!$E$10:$E$14,MATCH($B18,'Inventory Analysis'!$D$10:$D$14,0)) -> 28502
B19: Total | C19: =SUM(C14:C18) -> 812043 | D19: =SUM(D14:D18) -> 641347 | E19: =SUM(E14:E18) -> 431485 | F19: =SUM(F14:F18) -> 170696
B21: Plant-wise Performance
B22: Plant | C22: Production | D22: Sales | E22: Revenue (Lakhs) | F22: Unsold Qty
B23: Bengaluru Plant | C23: =INDEX('Production Analysis'!$E$9:$E$14,MATCH($B23,'Production Analysis'!$D$9:$D$14,0)) -> 176750 | D23: =INDEX('Sales Analysis'!$E$9:$E$14,MATCH($B23,'Sales Analysis'!$D$9:$D$14,0)) -> 142085 | E23: =INDEX('Revenue Analysis'!$D$26:$D$31,MATCH($B23,'Revenue Analysis'!$C$26:$C$31,0)) -> 93530 | F23: =INDEX('Inventory Analysis'!$E$27:$E$32,MATCH($B23,'Inventory Analysis'!$D$27:$D$32,0)) -> 34665
B24: Chennai Plant | C24: =INDEX('Production Analysis'!$E$9:$E$14,MATCH($B24,'Production Analysis'!$D$9:$D$14,0)) -> 132193 | D24: =INDEX('Sales Analysis'!$E$9:$E$14,MATCH($B24,'Sales Analysis'!$D$9:$D$14,0)) -> 106906 | E24: =INDEX('Revenue Analysis'!$D$26:$D$31,MATCH($B24,'Revenue Analysis'!$C$26:$C$31,0)) -> 69804 | F24: =INDEX('Inventory Analysis'!$E$27:$E$32,MATCH($B24,'Inventory Analysis'!$D$27:$D$32,0)) -> 25287
B25: Noida Plant | C25: =INDEX('Production Analysis'!$E$9:$E$14,MATCH($B25,'Production Analysis'!$D$9:$D$14,0)) -> 162038 | D25: =INDEX('Sales Analysis'!$E$9:$E$14,MATCH($B25,'Sales Analysis'!$D$9:$D$14,0)) -> 124925 | E25: =INDEX('Revenue Analysis'!$D$26:$D$31,MATCH($B25,'Revenue Analysis'!$C$26:$C$31,0)) -> 94173 | F25: =INDEX('Inventory Analysis'!$E$27:$E$32,MATCH($B25,'Inventory Analysis'!$D$27:$D$32,0)) -> 37113
B26: Pune Plant | C26: =INDEX('Production Analysis'!$E$9:$E$14,MATCH($B26,'Production Analysis'!$D$9:$D$14,0)) -> 174566 | D26: =INDEX('Sales Analysis'!$E$9:$E$14,MATCH($B26,'Sales Analysis'!$D$9:$D$14,0)) -> 138095 | E26: =INDEX('Revenue Analysis'!$D$26:$D$31,MATCH($B26,'Revenue Analysis'!$C$26:$C$31,0)) -> 85252 | F26: =INDEX('Inventory Analysis'!$E$27:$E$32,MATCH($B26,'Inventory Analysis'!$D$27:$D$32,0)) -> 36471
B27: Sriperumbudur Plant | C27: =INDEX('Production Analysis'!$E$9:$E$14,MATCH($B27,'Production Analysis'!$D$9:$D$14,0)) -> 151927 | D27: =INDEX('Sales Analysis'!$E$9:$E$14,MATCH($B27,'Sales Analysis'!$D$9:$D$14,0)) -> 117214 | E27: =INDEX('Revenue Analysis'!$D$26:$D$31,MATCH($B27,'Revenue Analysis'!$C$26:$C$31,0)) -> 83144 | F27: =INDEX('Inventory Analysis'!$E$27:$E$32,MATCH($B27,'Inventory Analysis'!$D$27:$D$32,0)) -> 34713
B28: Unknown Plant | C28: =INDEX('Production Analysis'!$E$9:$E$14,MATCH($B28,'Production Analysis'!$D$9:$D$14,0)) -> 14569 | D28: =INDEX('Sales Analysis'!$E$9:$E$14,MATCH($B28,'Sales Analysis'!$D$9:$D$14,0)) -> 12122 | E28: =INDEX('Revenue Analysis'!$D$26:$D$31,MATCH($B28,'Revenue Analysis'!$C$26:$C$31,0)) -> 5582 | F28: =INDEX('Inventory Analysis'!$E$27:$E$32,MATCH($B28,'Inventory Analysis'!$D$27:$D$32,0)) -> 2447
B29: Total | C29: =SUM(C23:C28) -> 812043 | D29: =SUM(D23:D28) -> 641347 | E29: =SUM(E23:E28) -> 431485 | F29: =SUM(F23:F28) -> 170696
B31: Model Performance (sorted by Sales, desc.)
B32: Model | C32: Production | D32: Sales | E32: Revenue (Lakhs) | F32: Unsold Qty
B33: Vivo Y300 | C33: =INDEX('Production Analysis'!$H$9:$H$23,MATCH($B33,'Production Analysis'!$G$9:$G$23,0)) -> 78592 | D33: =INDEX('Sales Analysis'!$H$6:$H$20,MATCH($B33,'Sales Analysis'!$G$6:$G$20,0)) -> 62246 | E33: =INDEX('Revenue Analysis'!$D$39:$D$53,MATCH($B33,'Revenue Analysis'!$C$39:$C$53,0)) -> 40249 | F33: =INDEX('Inventory Analysis'!$E$42:$E$56,MATCH($B33,'Inventory Analysis'!$D$42:$D$56,0)) -> 16346
B34: iPhone 16 | C34: =INDEX('Production Analysis'!$H$9:$H$23,MATCH($B34,'Production Analysis'!$G$9:$G$23,0)) -> 76202 | D34: =INDEX('Sales Analysis'!$H$6:$H$20,MATCH($B34,'Sales Analysis'!$G$6:$G$20,0)) -> 61231 | E34: =INDEX('Revenue Analysis'!$D$39:$D$53,MATCH($B34,'Revenue Analysis'!$C$39:$C$53,0)) -> 42298 | F34: =INDEX('Inventory Analysis'!$E$42:$E$56,MATCH($B34,'Inventory Analysis'!$D$42:$D$56,0)) -> 14971
B35: Galaxy A55 | C35: =INDEX('Production Analysis'!$H$9:$H$23,MATCH($B35,'Production Analysis'!$G$9:$G$23,0)) -> 70263 | D35: =INDEX('Sales Analysis'!$H$6:$H$20,MATCH($B35,'Sales Analysis'!$G$6:$G$20,0)) -> 56200 | E35: =INDEX('Revenue Analysis'!$D$39:$D$53,MATCH($B35,'Revenue Analysis'!$C$39:$C$53,0)) -> 39701 | F35: =INDEX('Inventory Analysis'!$E$42:$E$56,MATCH($B35,'Inventory Analysis'!$D$42:$D$56,0)) -> 14063
B36: OnePlus 13R | C36: =INDEX('Production Analysis'!$H$9:$H$23,MATCH($B36,'Production Analysis'!$G$9:$G$23,0)) -> 65435 | D36: =INDEX('Sales Analysis'!$H$6:$H$20,MATCH($B36,'Sales Analysis'!$G$6:$G$20,0)) -> 51926 | E36: =INDEX('Revenue Analysis'!$D$39:$D$53,MATCH($B36,'Revenue Analysis'!$C$39:$C$53,0)) -> 31483 | F36: =INDEX('Inventory Analysis'!$E$42:$E$56,MATCH($B36,'Inventory Analysis'!$D$42:$D$56,0)) -> 13509
B37: Xiaomi 14 | C37: =INDEX('Production Analysis'!$H$9:$H$23,MATCH($B37,'Production Analysis'!$G$9:$G$23,0)) -> 59936 | D37: =INDEX('Sales Analysis'!$H$6:$H$20,MATCH($B37,'Sales Analysis'!$G$6:$G$20,0)) -> 48709 | E37: =INDEX('Revenue Analysis'!$D$39:$D$53,MATCH($B37,'Revenue Analysis'!$C$39:$C$53,0)) -> 32107 | F37: =INDEX('Inventory Analysis'!$E$42:$E$56,MATCH($B37,'Inventory Analysis'!$D$42:$D$56,0)) -> 11227
B38: OnePlus 13 | C38: =INDEX('Production Analysis'!$H$9:$H$23,MATCH($B38,'Production Analysis'!$G$9:$G$23,0)) -> 59469 | D38: =INDEX('Sales Analysis'!$H$6:$H$20,MATCH($B38,'Sales Analysis'!$G$6:$G$20,0)) -> 45183 | E38: =INDEX('Revenue Analysis'!$D$39:$D$53,MATCH($B38,'Revenue Analysis'!$C$39:$C$53,0)) -> 26450 | F38: =INDEX('Inventory Analysis'!$E$42:$E$56,MATCH($B38,'Inventory Analysis'!$D$42:$D$56,0)) -> 14286
B39: Galaxy M35 | C39: =INDEX('Production Analysis'!$H$9:$H$23,MATCH($B39,'Production Analysis'!$G$9:$G$23,0)) -> 56906 | D39: =INDEX('Sales Analysis'!$H$6:$H$20,MATCH($B39,'Sales Analysis'!$G$6:$G$20,0)) -> 43792 | E39: =INDEX('Revenue Analysis'!$D$39:$D$53,MATCH($B39,'Revenue Analysis'!$C$39:$C$53,0)) -> 25165 | F39: =INDEX('Inventory Analysis'!$E$42:$E$56,MATCH($B39,'Inventory Analysis'!$D$42:$D$56,0)) -> 13114
B40: Vivo T3 | C40: =INDEX('Production Analysis'!$H$9:$H$23,MATCH($B40,'Production Analysis'!$G$9:$G$23,0)) -> 49157 | D40: =INDEX('Sales Analysis'!$H$6:$H$20,MATCH($B40,'Sales Analysis'!$G$6:$G$20,0)) -> 37042 | E40: =INDEX('Revenue Analysis'!$D$39:$D$53,MATCH($B40,'Revenue Analysis'!$C$39:$C$53,0)) -> 30952 | F40: =INDEX('Inventory Analysis'!$E$42:$E$56,MATCH($B40,'Inventory Analysis'!$D$42:$D$56,0)) -> 12115
B41: Redmi Note 14 | C41: =INDEX('Production Analysis'!$H$9:$H$23,MATCH($B41,'Production Analysis'!$G$9:$G$23,0)) -> 45410 | D41: =INDEX('Sales Analysis'!$H$6:$H$20,MATCH($B41,'Sales Analysis'!$G$6:$G$20,0)) -> 36098 | E41: =INDEX('Revenue Analysis'!$D$39:$D$53,MATCH($B41,'Revenue Analysis'!$C$39:$C$53,0)) -> 24939 | F41: =INDEX('Inventory Analysis'!$E$42:$E$56,MATCH($B41,'Inventory Analysis'!$D$42:$D$56,0)) -> 9312
B42: iPhone 16 Plus | C42: =INDEX('Production Analysis'!$H$9:$H$23,MATCH($B42,'Production Analysis'!$G$9:$G$23,0)) -> 42835 | D42: =INDEX('Sales Analysis'!$H$6:$H$20,MATCH($B42,'Sales Analysis'!$G$6:$G$20,0)) -> 35130 | E42: =INDEX('Revenue Analysis'!$D$39:$D$53,MATCH($B42,'Revenue Analysis'!$C$39:$C$53,0)) -> 32636 | F42: =INDEX('Inventory Analysis'!$E$42:$E$56,MATCH($B42,'Inventory Analysis'!$D$42:$D$56,0)) -> 7705
B43: Vivo V40 | C43: =INDEX('Production Analysis'!$H$9:$H$23,MATCH($B43,'Production Analysis'!$G$9:$G$23,0)) -> 43464 | D43: =INDEX('Sales Analysis'!$H$6:$H$20,MATCH($B43,'Sales Analysis'!$G$6:$G$20,0)) -> 35029 | E43: =INDEX('Revenue Analysis'!$D$39:$D$53,MATCH($B43,'Revenue Analysis'!$C$39:$C$53,0)) -> 20070 | F43: =INDEX('Inventory Analysis'!$E$42:$E$56,MATCH($B43,'Inventory Analysis'!$D$42:$D$56,0)) -> 8435
B44: iPhone 15 | C44: =INDEX('Production Analysis'!$H$9:$H$23,MATCH($B44,'Production Analysis'!$G$9:$G$23,0)) -> 43220 | D44: =INDEX('Sales Analysis'!$H$6:$H$20,MATCH($B44,'Sales Analysis'!$G$6:$G$20,0)) -> 34172 | E44: =INDEX('Revenue Analysis'!$D$39:$D$53,MATCH($B44,'Revenue Analysis'!$C$39:$C$53,0)) -> 22518 | F44: =INDEX('Inventory Analysis'!$E$42:$E$56,MATCH($B44,'Inventory Analysis'!$D$42:$D$56,0)) -> 9048
... B47: Galaxy S24 | C47: =INDEX('Production Analysis'!$H$9:$H$23,MATCH($B47,'Production Analysis'!$G$9:$G$23,0)) -> 39937 | D47: =INDEX('Sales Analysis'!$H$6:$H$20,MATCH($B47,'Sales Analysis'!$G$6:$G$20,0)) -> 30390 | E47: =INDEX('Revenue Analysis'!$D$39:$D$53,MATCH($B47,'Revenue Analysis'!$C$39:$C$53,0)) -> 21023 | F47: =INDEX('Inventory Analysis'!$E$42:$E$56,MATCH($B47,'Inventory Analysis'!$D$42:$D$56,0)) -> 9547
B48: Total | C48: =SUM(C33:C47) -> 812043 | D48: =SUM(D33:D47) -> 641347 | E48: =SUM(E33:E47) -> 431485 | F48: =SUM(F33:F47) -> 170696
B50: Monthly Trend
...

Sheet Raw Data
A1: Serial No | B1: Plant Name | C1: Plant Type | D1: Brand | E1: Product | F1: Model | G1: Production Date | H1: Quantity Produced | I1: Quantity Sold | J1: Unit Price | K1: Shipping Status | L1: Completion Status
A2: 1 | B2: Noida Plant | C2: Packaging | D2: Samsung | E2: Smartphone | F2: Galaxy A55 | G2: 2025-02-22 | H2: 4591 | I2: 3732 | J2: 19523 | K2: Pending | L2: Completed
A3: 2 | B3: Bengaluru Plant | C3: Manufacturing | D3: Samsung | E3: Smartphone | F3: Galaxy M35 | G3: 2025-10-26 | H3: 4273 | I3: 3023 | J3: 84627 | K3: In Transit | L3: In Progress
A4: 3 | B4: Bengaluru Plant | C4: Testing | D4: Samsung | E4: Smartphone | F4: Galaxy M35 | G4: 2025-08-17 | H4: 4734 | I4: 4061 | J4: 45531 | K4: In Transit | L4: Completed
A5: 4 | B5: Noida Plant | C5: Manufacturing | D5: Samsung | E5: Smartphone | F5: Galaxy A55 | G5: 2025-08-22 | H5: 2255 | I5: 1609 | J5: 103791 | K5: Pending | L5: Completed
A6: 5 | B6: Sriperumbudur Plant | C6: Packaging | D6: Samsung | E6: Smartphone | F6: Galaxy S24 | G6: 2025-03-22 | H6: 957 | I6: 760 | J6: 100782 | K6: Pending | L6: In Progress
A7: 6 | B7: Sriperumbudur Plant | C7: Testing | D7: Samsung | E7: Smartphone | F7: Galaxy M35 | G7: 2025-07-16 | H7: 4604 | I7: 3470 | J7: 53473 | K7: Shipped | L7: In Progress
A8: 7 | B8: Bengaluru Plant | C8: Manufacturing | D8: Samsung | E8: Smartphone | F8: Galaxy S24 | G8: 2025-05-17 | H8: 2411 | I8: 1484 | J8: 13866 | K8: Pending | L8: In Progress
A9: 8 | B9: Pune Plant | C9: Packaging | D9: Samsung | E9: Smartphone | F9: Galaxy M35 | G9: 2025-07-10 | H9: 536 | I9: 337 | J9: 82994 | K9: Shipped | L9: In Progress
A10: 9 | B10: Noida Plant | C10: Testing | D10: Samsung | E10: Smartphone | F10: Galaxy A55 | G10: 2025-01-24 | H10: 511 | I10: 340 | J10: 27053 | K10: Shipped | L10: In Progress
A11: 10 | B11: Noida Plant | C11: Testing | D11: Samsung | E11: Smartphone | F11: Galaxy M35 | G11: 2025-02-28 | H11: 1567 | I11: 1147 | J11: 59010 | K11: Pending | L11: Completed
A12: 11 | B12: Pune Plant | C12: Testing | D12: Samsung | E12: Smartphone | F12: Galaxy A55 | G12: 2025-01-09 | H12: 2747 | I12: 2074 | J12: 28486 | K12: In Transit | L12: In Progress
A13: 12 | B13: Noida Plant | C13: Packaging | D13: Samsung | E13: Smartphone | F13: Galaxy A55 | G13: 2025-06-10 | H13: 1546 | I13: 988 | J13: 36513 | K13: Shipped | L13: In Progress
... A52: 51 | B52: Bengaluru Plant | C52: Assembly | D52: Samsung | E52: Smartphone | F52: Galaxy M35 | G52: 2025-03-28 | H52: 3091 | I52: 3061 | J52: 30900 | K52: Shipped | L52: Completed
A53: 52 | C53: Packaging | D53: Samsung | E53: Smartphone | F53: Galaxy M35 | G53: 2025-08-07 | H53: 1015 | I53: 673 | J53: 62569 | K53: Shipped | L53: In Progress
A54: 53 | C54: Testing | D54: Samsung | E54: Smartphone | F54: Galaxy M35 | G54: 2025-02-06 | H54: 3608 | I54: 2407 | J54: 48615 | K54: In Transit | L54: In Progress
A55: 54 | B55: Bengaluru Plant | C55: Testing | D55: Samsung | E55: Smartphone | F55: Galaxy M35 | G55: 2025-06-29 | H55: 4400 | I55: 3146 | J55: 53462 | L55: Completed
A56: 55 | B56: Bengaluru Plant | C56: Assembly | D56: Samsung | E56: Smartphone | F56: Galaxy A55 | G56: 2025-02-04 | H56: 4009 | I56: 3805 | J56: 113250 | K56: In Transit | L56: In Progress
A57: 56 | B57: Noida Plant | C57: Testing | D57: Samsung | E57: Smartphone | F57: Galaxy A55 | G57: 2025-12-12 | H57: 4658 | I57: 2982 | J57: 115861 | K57: In Transit | L57: Completed
A58: 57 | B58: Chennai Plant | C58: Testing | D58: Samsung | E58: Smartphone | F58: Galaxy M35 | G58: 2025-04-18 | H58: 4907 | I58: 3017 | J58: 83238 | K58: In Transit | L58: Completed
A59: 58 | B59: Pune Plant | C59: Manufacturing | D59: Samsung | E59: Smartphone | F59: Galaxy S24 | G59: 2025-11-13 | H59: 1329 | I59: 832 | J59: 96946 | K59: In Transit | L59: In Progress
A60: 59 | B60: Sriperumbudur Plant | C60: Testing | D60: Samsung | E60: Smartphone | F60: Galaxy M35 | G60: 2025-08-03 | H60: 2621 | I60: 1921 | J60: 73247 | K60: Pending | L60: Completed
A61: 60 | B61: Pune Plant | C61: Testing | D61: Samsung | E61: Smartphone | F61: Galaxy M35 | G61: 2025-01-15 | H61: 4198 | I61: 4172 | J61: 29307 | K61: Shipped | L61: Completed
A62: 61 | B62: Chennai Plant | C62: Manufacturing | D62: Apple | E62: Smartphone | F62: iPhone 16 | G62: 2025-03-27 | H62: 2335 | I62: 2237 | J62: 44124 | K62: Pending | L62: Completed
A63: 62 | B63: Sriperumbudur Plant | C63: Testing | D63: Apple | E63: Smartphone | F63: iPhone 15 | G63: 2025-11-23 | H63: 2998 | I63: 2046 | J63: 96244 | K63: Pending | L63: Completed
A64: 63 | B64: Noida Plant | C64: Manufacturing | D64: Apple | E64: Smartphone | F64: iPhone 16 | G64: 2025-08-19 | H64: 1238 | I64: 872 | J64: 110413 | K64: In Transit | L64: Completed
A65: 64 | B65: Bengaluru Plant | C65: Assembly | D65: Apple | E65: Smartphone | F65: iPhone 16 | G65: 2025-10-08 | H65: 3946 | I65: 2563 | J65: 97923 | K65: Pending | L65: Completed
A66: 65 | B66: Bengaluru Plant | C66: Packaging | D66: Apple | E66: Smartphone | F66: iPhone 16 | G66: 2025-08-25 | H66: 739 | I66: 735 | J66: 87242 | K66: Pending | L66: In Progress
A67: 66 | B67: Bengaluru Plant | C67: Packaging | D67: Apple | E67: Smartphone | F67: iPhone 16 | G67: 2025-08-28 | H67: 4423 | I67: 3783 | J67: 57138 | K67: In Transit | L67: Completed
... A70: 68 | B70: Sriperumbudur Plant | C70: Testing | D70: Apple | E70: Smartphone | F70: iPhone 15 | G70: 2025-12-08 | H70: 2603 | I70: 2407 | J70: 104598 | K70: Pending | L70: Completed
A71: 70 | C71: Packaging | D71: Apple | E71: Smartphone | F71: iPhone 15 | G71: 2025-02-09 | H71: 3049 | I71: 2976 | J71: 57913 | K71: In Transit | L71: In Progress
A72: 71 | B72: Bengaluru Plant | C72: Testing | D72: Apple | E72: Smartphone | F72: iPhone 16 | G72: 2025-09-27 | H72: 4066 | I72: 3216 | J72: 85071 | K72: Pending | L72: Completed
A73: 72 | B73: Chennai Plant | C73: Packaging | D73: Apple | E73: Smartphone | F73: iPhone 16 | G73: 2025-12-14 | H73: 4685 | I73: 3175 | J73: 93915 | K73: Shipped | L73: Completed
A74: 73 | B74: Pune Plant | C74: Manufacturing | D74: Apple | E74: Smartphone | F74: iPhone 15 | G74: 2025-12-29 | H74: 2652 | I74: 2359 | J74: 87314 | K74: In Transit | L74: In Progress
A75: 74 | C75: Assembly | D75: Apple | E75: Smartphone | F75: iPhone 16 Plus | G75: 2025-10-30 | H75: 3426 | I75: 2703 | J75: 18687 | K75: Pending | L75: Completed
A76: 75 | B76: Noida Plant | C76: Testing | D76: Apple | E76: Smartphone | F76: iPhone 15 | G76: 2025-02-03 | H76: 2960 | I76: 2184 | J76: 81256 | K76: In Transit | L76: Completed
A77: 76 | B77: Bengaluru Plant | C77: Packaging | D77: Apple | E77: Smartphone | F77: iPhone 15 | G77: 2025-07-08 | H77: 1552 | I77: 1067 | J77: 23884 | K77: Shipped | L77: Completed
A78: 77 | B78: Chennai Plant | C78: Packaging | D78: Apple | E78: Smartphone | F78: iPhone 15 | G78: 2025-02-27 | H78: 1408 | I78: 1261 | J78: 67153 | K78: In Transit | L78: In Progress
A79: 78 | B79: Sriperumbudur Plant | C79: Assembly | D79: Apple | E79: Smartphone | F79: iPhone 15 | G79: 2025-08-26 | H79: 1688 | I79: 1362 | J79: 85629 | K79: In Transit | L79: In Progress
A80: 79 | B80: Noida Plant | C80: Assembly | D80: Apple | E80: Smartphone | F80: iPhone 16 Plus | G80: 2025-08-27 | H80: 4465 | I80: 3637 | J80: 93822 | K80: Shipped | L80: Completed
...

Sheet Cleaned Data
A1: Serial No | B1: Plant Name | C1: Plant Type | D1: Brand | E1: Product | F1: Model | G1: Production Date | H1: Quantity Produced | I1: Quantity Sold | J1: Unit Price | K1: Shipping Status | L1: Completion Status | M1: Revenue | N1: Revenue (Crores) | O1: Unsold Quantity | P1: Month | Q1: Year
A2: 1 | B2: Noida Plant | C2: Packaging | D2: Samsung | E2: Smartphone | F2: Galaxy A55 | G2: 2025-02-22 | H2: 4591 | I2: 3732 | J2: 19523 | K2: Pending | L2: Completed | M2: =I2*J2 | N2: =ROUND(M2/100000, 0) | O2: =H2-I2 | P2: =TEXT(G2,"mmmm") | Q2: =YEAR(G2)
A3: 2 | B3: Bengaluru Plant | C3: Manufacturing | D3: Samsung | E3: Smartphone | F3: Galaxy M35 | G3: 2025-10-26 | H3: 4273 | I3: 3023 | J3: 84627 | K3: In Transit | L3: In Progress | M3: =I3*J3 | N3: =ROUND(M3/100000, 0) | O3: =H3-I3 | P3: =TEXT(G3,"mmmm") | Q3: =YEAR(G3)
A4: 3 | B4: Bengaluru Plant | C4: Testing | D4: Samsung | E4: Smartphone | F4: Galaxy M35 | G4: 2025-08-17 | H4: 4734 | I4: 4061 | J4: 45531 | K4: In Transit | L4: Completed | M4: =I4*J4 | N4: =ROUND(M4/100000, 0) | O4: =H4-I4 | P4: =TEXT(G4,"mmmm") | Q4: =YEAR(G4)
A5: 4 | B5: Noida Plant | C5: Manufacturing | D5: Samsung | E5: Smartphone | F5: Galaxy A55 | G5: 2025-08-22 | H5: 2255 | I5: 1609 | J5: 103791 | K5: Pending | L5: Completed | M5: =I5*J5 | N5: =ROUND(M5/100000, 0) | O5: =H5-I5 | P5: =TEXT(G5,"mmmm") | Q5: =YEAR(G5)
A6: 5 | B6: Sriperumbudur Plant | C6: Packaging | D6: Samsung | E6: Smartphone | F6: Galaxy S24 | G6: 2025-03-22 | H6: 957 | I6: 760 | J6: 100782 | K6: Pending | L6: In Progress | M6: =I6*J6 | N6: =ROUND(M6/100000, 0) | O6: =H6-I6 | P6: =TEXT(G6,"mmmm") | Q6: =YEAR(G6)
A7: 6 | B7: Sriperumbudur Plant | C7: Testing | D7: Samsung | E7: Smartphone | F7: Galaxy M35 | G7: 2025-07-16 | H7: 4604 | I7: 3470 | J7: 53473 | K7: Shipped | L7: In Progress | M7: =I7*J7 | N7: =ROUND(M7/100000, 0) | O7: =H7-I7 | P7: =TEXT(G7,"mmmm") | Q7: =YEAR(G7)
A8: 7 | B8: Bengaluru Plant | C8: Manufacturing | D8: Samsung | E8: Smartphone | F8: Galaxy S24 | G8: 2025-05-17 | H8: 2411 | I8: 1484 | J8: 13866 | K8: Pending | L8: In Progress | M8: =I8*J8 | N8: =ROUND(M8/100000, 0) | O8: =H8-I8 | P8: =TEXT(G8,"mmmm") | Q8: =YEAR(G8)
A9: 8 | B9: Pune Plant | C9: Packaging | D9: Samsung | E9: Smartphone | F9: Galaxy M35 | G9: 2025-07-10 | H9: 536 | I9: 337 | J9: 82994 | K9: Shipped | L9: In Progress | M9: =I9*J9 | N9: =ROUND(M9/100000, 0) | O9: =H9-I9 | P9: =TEXT(G9,"mmmm") | Q9: =YEAR(G9)
A10: 9 | B10: Noida Plant | C10: Testing | D10: Samsung | E10: Smartphone | F10: Galaxy A55 | G10: 2025-01-24 | H10: 511 | I10: 340 | J10: 27053 | K10: Shipped | L10: In Progress | M10: =I10*J10 | N10: =ROUND(M10/100000, 0) | O10: =H10-I10 | P10: =TEXT(G10,"mmmm") | Q10: =YEAR(G10)
A11: 10 | B11: Noida Plant | C11: Testing | D11: Samsung | E11: Smartphone | F11: Galaxy M35 | G11: 2025-02-28 | H11: 1567 | I11: 1147 | J11: 59010 | K11: Pending | L11: Completed | M11: =I11*J11 | N11: =ROUND(M11/100000, 0) | O11: =H11-I11 | P11: =TEXT(G11,"mmmm") | Q11: =YEAR(G11)
A12: 11 | B12: Pune Plant | C12: Testing | D12: Samsung | E12: Smartphone | F12: Galaxy A55 | G12: 2025-01-09 | H12: 2747 | I12: 2074 | J12: 28486 | K12: In Transit | L12: In Progress | M12: =I12*J12 | N12: =ROUND(M12/100000, 0) | O12: =H12-I12 | P12: =TEXT(G12,"mmmm") | Q12: =YEAR(G12)
A13: 12 | B13: Noida Plant | C13: Packaging | D13: Samsung | E13: Smartphone | F13: Galaxy A55 | G13: 2025-06-10 | H13: 1546 | I13: 988 | J13: 36513 | K13: Shipped | L13: In Progress | M13: =I13*J13 | N13: =ROUND(M13/100000, 0) | O13: =H13-I13 | P13: =TEXT(G13,"mmmm") | Q13: =YEAR(G13)
... A269: 277 | B269: Bengaluru Plant | C269: Packaging | D269: Oneplus | E269: Smartphone | F269: OnePlus 13 | G269: 2025-12-12 | H269: 4322 | I269: 3771 | J269: 21983 | K269: Shipped | L269: Completed | M269: =I269*J269 | N269: =ROUND(M269/100000, 0) | O269: =H269-I269 | P269: =TEXT(G269,"mmmm") | Q269: =YEAR(G269)
A270: 278 | B270: Sriperumbudur Plant | C270: Testing | D270: Oneplus | E270: Smartphone | F270: OnePlus 13R | G270: 2025-04-08 | H270: 3946 | I270: 2727 | J270: 26805 | K270: Shipped | L270: Completed | M270: =I270*J270 | N270: =ROUND(M270/1000000, 0) | O270: =H270-I270 | P270: =TEXT(G270,"mmmm") | Q270: =YEAR(G270)
A271: 280 | B271: Bengaluru Plant | C271: Testing | D271: Oneplus | E271: Smartphone | F271: OnePlus 13R | G271: 2025-10-21 | H271: 838 | I271: 750 | J271: 34584 | K271: In Transit | L271: In Progress | M271: =I271*J271 | N271: =ROUND(M271/1000000, 0) | O271: =H271-I271 | P271: =TEXT(G271,"mmmm") | Q271: =YEAR(G271)
A272: 281 | B272: Sriperumbudur Plant | C272: Assembly | D272: Oneplus | E272: Smartphone | F272: OnePlus 13 | G272: 2025-12-10 | H272: 3826 | I272: 2446 | J272: 14911 | K272: Pending | L272: Completed | M272: =I272*J272 | N272: =ROUND(M272/1000000, 0) | O272: =H272-I272 | P272: =TEXT(G272,"mmmm") | Q272: =YEAR(G272)
A273: 282 | B273: Chennai Plant | C273: Packaging | D273: Oneplus | E273: Smartphone | F273: OnePlus Nord 5 | G273: 2025-10-16 | H273: 4230 | I273: 2955 | J273: 88320 | K273: Shipped | L273: Completed | M273: =I273*J273 | N273: =ROUND(M273/1000000, 0) | O273: =H273-I273 | P273: =TEXT(G273,"mmmm") | Q273: =YEAR(G273)
A274: 283 | B274: Chennai Plant | C274: Testing | D274: Oneplus | E274: Smartphone | F274: OnePlus Nord 5 | G274: 2025-05-15 | H274: 2775 | I274: 1878 | J274: 43228 | K274: Shipped | L274: In Progress | M274: =I274*J274 | N274: =ROUND(M274/1000000, 0) | O274: =H274-I274 | P274: =TEXT(G274,"mmmm") | Q274: =YEAR(G274)
A275: 284 | B275: Sriperumbudur Plant | C275: Manufacturing | D275: Oneplus | E275: Smartphone | F275: OnePlus 13R | G275: 2025-07-06 | H275: 4793 | I275: 3082 | J275: 95770 | K275: In Transit | L275: In Progress | M275: =I275*J275 | N275: =ROUND(M275/1000000, 0) | O275: =H275-I275 | P275: =TEXT(G275,"mmmm") | Q275: =YEAR(G275)
A276: 285 | B276: Sriperumbudur Plant | C276: Manufacturing | D276: Oneplus | E276: Smartphone | F276: OnePlus 13R | G276: 2025-01-23 | H276: 4981 | I276: 4898 | J276: 18626 | K276: Shipped | L276: In Progress | M276: =I276*J276 | N276: =ROUND(M276/1000000, 0) | O276: =H276-I276 | P276: =TEXT(G276,"mmmm") | Q276: =YEAR(G276)
A277: 286 | B277: Noida Plant | C277: Testing | D277: Oneplus | E277: Smartphone | F277: OnePlus 13 | G277: 2025-01-03 | H277: 2207 | I277: 2088 | J277: 112423 | K277: Pending | L277: In Progress | M277: =I277*J277 | N277: =ROUND(M277/1000000, 0) | O277: =H277-I277 | P277: =TEXT(G277,"mmmm") | Q277: =YEAR(G277)
A278: 287 | B278: Pune Plant | C278: Manufacturing | D278: Oneplus | E278: Smartphone | F278: OnePlus Nord 5 | G278: 2025-12-16 | H278: 4891 | I278: 4376 | J278: 103003 | K278: Pending | L278: In Progress | M278: =I278*J278 | N278: =ROUND(M278/1000000, 0) | O278: =H278-I278 | P278: =TEXT(G278,"mmmm") | Q278: =YEAR(G278)
A279: 288 | B279: Noida Plant | C279: Packaging | D279: Oneplus | E279: Smartphone | F279: OnePlus Nord 5 | G279: 2025-05-31 | H279: 3040 | I279: 1973 | J279: 55486 | K279: Pending | L279: Completed | M279: =I279*J279 | N279: =ROUND(M279/1000000, 0) | O279: =H279-I279 | P279: =TEXT(G279,"mmmm") | Q279: =YEAR(G279)
A280: 289 | B280: Noida Plant | C280: Manufacturing | D280: Oneplus | E280: Smartphone | F280: OnePlus 13R | G280: 2025-02-04 | H280: 2806 | I280: 2480 | J280: 60915 | K280: Shipped | L280: Completed | M280: =I280*J280 | N280: =ROUND(M280/1000000, 0) | O280: =H280-I280 | P280: =TEXT(G280,"mmmm") | Q280: =YEAR(G280)
A281: 290 | B281: Chennai Plant | C281: Testing | D281: Oneplus | E281: Smartphone | F281: OnePlus 13R | G281: 2025-01-25 | H281: 3067 | I281: 2374 | J281: 21014 | K281: Shipped | L281: Completed | M281: =I281*J281 | N281: =ROUND(M281/1000000, 0) | O281: =H281-I281 | P281: =TEXT(G281,"mmmm") | Q281: =YEAR(G281)
... A291: 300 | B291: Pune Plant | C291: Assembly | D291: Oneplus | E291: Smartphone | F291: OnePlus Nord 5 | G291: 2025-05-31 | H291: 1218 | I291: 1201 | J291: 91690 | K291: In Transit | L291: Completed | M291: =I291*J291 | N291: =ROUND(M291/1000000, 0) | O291: =H291-I291 | P291: =TEXT(G291,"mmmm") | Q291: =YEAR(G291)

Sheet Production Analysis
B2: Total Production | D2: Total Brands | F2: Average Production | H2: Maxi Production | J2: Mini Production
B3: =SUM(Table1[Quantity Produced]) | D3: 5 | F3: =ROUND(AVERAGE('Cleaned Data'!H:H), 0) | H3: =MAX('Cleaned Data'!H:H) | J3: =MIN('Cleaned Data'!H:H)
A8: Row Labels | B8: Sum of Quantity Produced | D8: Row Labels | E8: Sum of Quantity Produced | G8: Row Labels | H8: Sum of Quantity Produced
A9: Apple | B9: 162257 | D9: Bengaluru Plant | E9: 176750 | G9: Galaxy A55 | H9: 70263
A10: Oneplus | B10: 167240 | D10: Chennai Plant | E10: 132193 | G10: Galaxy M35 | H10: 56906
A11: Samsung | B11: 167106 | D11: Noida Plant | E11: 162038 | G11: Galaxy S24 | H11: 39937
A12: Vivo | B12: 171213 | D12: Pune Plant | E12: 174566 | G12: iPhone 15 | H12: 43220
A13: Xiaomi | B13: 144227 | D13: Sriperumbudur Plant | E13: 151927 | G13: iPhone 16 | H13: 76202
A14: Grand Total | B14: 812043 | D14: Unknown Plant | E14: 14569 | G14: iPhone 16 Plus | H14: 42835
D15: Grand Total | E15: 812043 | G15: OnePlus 13 | H15: 59469
G16: OnePlus 13R | H16: 65435
G17: OnePlus Nord 5 | H17: 42336
G18: Redmi 14C | H18: 38881
G19: Redmi Note 14 | H19: 45410
G20: Vivo T3 | H20: 49157
G21: Vivo V40 | H21: 43464
G22: Vivo Y300 | H22: 78592
G23: Xiaomi 14 | H23: 59936
G24: Grand Total | H24: 812043
B36: Insights | D36: * Vivo has the highest production volume.
D37: * Bengaluru Plant contributes the highest production.
D38: * Vivo Y300 is the most produced model.

Sheet Sales Analysis
B2: Total Sales | D2: Average Sales | F2: Highest Sales | H2: Lowest Sales
B3: =SUM('Cleaned Data'!I:I) | D3: =ROUND(AVERAGE('Cleaned Data'!I:I), 0) | F3: =MAX('Cleaned Data'!I:I) | H3: =MIN('Cleaned Data'!I:I)
G5: Row Labels | H5: Sum of Quantity Sold
G6: Vivo Y300 | H6: 62246
G7: iPhone 16 | H7: 61231
A8: Row Labels | B8: Sum of Quantity Sold | D8: Row Labels | E8: Sum of Quantity Sold | G8: Galaxy A55 | H8: 56200
A9: Apple | B9: 130533 | D9: Bengaluru Plant | E9: 142085 | G9: OnePlus 13R | H9: 51926
A10: Oneplus | B10: 130390 | D10: Chennai Plant | E10: 106906 | G10: Xiaomi 14 | H10: 48709
A11: Samsung | B11: 130382 | D11: Noida Plant | E11: 124925 | G11: OnePlus 13 | H11: 45183
A12: Vivo | B12: 134317 | D12: Pune Plant | E12: 138095 | G12: Galaxy M35 | H12: 43792
A13: Xiaomi | B13: 115725 | D13: Sriperumbudur Plant | E13: 117214 | G13: Vivo T3 | H13: 37042
A14: Grand Total | B14: 641347 | D14: Unknown Plant | E14: 12122 | G14: Redmi Note 14 | H14: 36098
D15: Grand Total | E15: 641347 | G15: iPhone 16 Plus | H15: 35130
G16: Vivo V40 | H16: 35029
G17: iPhone 15 | H17: 34172
G18: OnePlus Nord 5 | H18: 33281
G19: Redmi 14C | H19: 30918
G20: Galaxy S24 | H20: 30390
G21: Grand Total | H21: 641347
B39: Insights | D39: * Vivo generated the highest sales volume.
D40: * Vivo Y300 is the best-selling model, indicating high customer demand.
D41: * Bengaluru Plant contributed the highest sales.

Sheet Revenue Analysis
B2: Total Revenue(in lakhs) | E2: Average Revenue(in lakhs) | I2: Highest Revenue(in lakhs) | N2: Lowest Revenue(in lakhs)
B3: =SUM(Table1[Revenue (Crores)]) | E3: =ROUND(AVERAGE(Table1[Revenue (Crores)]),0) | I3: =MAX(Table1[Revenue (Crores)]) | N3: =MIN(Table1[Revenue (Crores)])
C8: Row Labels | D8: Sum of Revenue (Lakhs)
C9: Apple | D9: 97452
C10: Oneplus | D10: 81796
C11: Samsung | D11: 85889
C12: Vivo | D12: 91271
C13: Xiaomi | D13: 75077
C14: Grand Total | D14: 431485
C25: Row Labels | D25: Sum of Revenue (Lakhs)
C26: Bengaluru Plant | D26: 93530
C27: Chennai Plant | D27: 69804
C28: Noida Plant | D28: 94173
C29: Pune Plant | D29: 85252
C30: Sriperumbudur Plant | D30: 83144
C31: Unknown Plant | D31: 5582
C32: Grand Total | D32: 431485
C38: Row Labels | D38: Sum of Revenue (Lakhs)
C39: Galaxy A55 | D39: 39701
C40: Galaxy M35 | D40: 25165
C41: Galaxy S24 | D41: 21023
C42: iPhone 15 | D42: 22518
C43: iPhone 16 | D43: 42298
C44: iPhone 16 Plus | D44: 32636
C45: OnePlus 13 | D45: 26450
C46: OnePlus 13R | D46: 31483
C47: OnePlus Nord 5 | D47: 23863
C48: Redmi 14C | D48: 18031
C49: Redmi Note 14 | D49: 24939
C50: Vivo T3 | D50: 30952
... C54: Grand Total | D54: 431485
C58: Insights | E58: * Apple is the highest revenue-generating brand with 97,452 Lakhs.
E59: * Bengaluru Plant generated the highest revenue among all manufacturing plants.
E60: * iPhone 16 is the highest revenue-generating smartphone model.
E61: * Premium smartphones contribute significantly to overall business revenue despite higher prices.

Sheet Inventory Analysis
B2: Total Inventory | E2: Total Inventory Sold | I2: Total Unsold Inventory | M2: Inventory Utilization %
B3: =SUM('Cleaned Data'!H:H) | E3: =SUM('Cleaned Data'!I:I) | I3: =SUM('Cleaned Data'!O:O) | M3: =(SUM(Table1[Quantity Sold])/SUM(Table1[Quantity Produced]))
D9: Row Labels | E9: Sum of Unsold Quantity
D10: Apple | E10: 31724
D11: Oneplus | E11: 36850
D12: Samsung | E12: 36724
D13: Vivo | E13: 36896
D14: Xiaomi | E14: 28502
D15: Grand Total | E15: 170696
D26: Row Labels | E26: Sum of Unsold Quantity
D27: Bengaluru Plant | E27: 34665
D28: Chennai Plant | E28: 25287
D29: Noida Plant | E29: 37113
D30: Pune Plant | E30: 36471
D31: Sriperumbudur Plant | E31: 34713
D32: Unknown Plant | E32: 2447
D33: Grand Total | E33: 170696
D41: Row Labels | E41: Sum of Unsold Quantity
D42: iPhone 16 Plus | E42: 7705
D43: Redmi 14C | E43: 7963
D44: Vivo V40 | E44: 8435
D45: iPhone 15 | E45: 9048
D46: OnePlus Nord 5 | E46: 9055
D47: Redmi Note 14 | E47: 9312
D48: Galaxy S24 | E48: 9547
D49: Xiaomi 14 | E49: 11227
D50: Vivo T3 | E50: 12115
D51: Galaxy M35 | E51: 13114
D52: OnePlus 13R | E52: 13509
D53: Galaxy A55 | E53: 14063
... D57: Grand Total | E57: 170696
C67: Insights | E67: * Vivo recorded the highest unsold inventory (36,896 units).
E68: * Noida Plant has the highest remaining stock (37,113 units).
E69: * Vivo Y300 is the model with the highest unsold quantity (16,346 units).
E70: * Better demand forecasting can help reduce excess inventory and improve inventory utilization.

Sheet Monthly Trend Analysis
C2: Total Production | H2: Total Sales | M2: Total Revenue(in Crores)
C3: =SUM(Table1[Quantity Produced]) | H3: =SUM(Table1[Quantity Sold]) | M3: =SUM(Table1[Revenue (Crores)])
D10: Row Labels | E10: Sum of Quantity Produced
D11: January | E11: 61476
D12: February | E12: 71432
D13: March | E13: 50498
D14: April | E14: 56831
D15: May | E15: 79080
D16: June | E16: 81788
D17: July | E17: 60864
D18: August | E18: 85251
D19: September | E19: 44584
D20: October | E20: 75863
D21: November | E21: 65195
D22: December | E22: 79181
D23: Grand Total | E23: 812043
D30: Row Labels | E30: Sum of Quantity Sold
D31: January | E31: 49781
D32: February | E32: 57900
D33: March | E33: 39443
D34: April | E34: 45418
D35: May | E35: 62241
D36: June | E36: 62355
D37: July | E37: 45464
D38: August | E38: 68283
D39: September | E39: 34925
D40: October | E40: 60062
D41: November | E41: 53895
D42: December | E42: 61580
D43: Grand Total | E43: 641347
D50: Row Labels | E50: Sum of Revenue (Lakhs)
D51: January | E51: 25029
D52: February | E52: 41044
D53: March | E53: 28278
D54: April | E54: 29479
D55: May | E55: 34016
D56: June | E56: 42506
D57: July | E57: 32163
D58: August | E58: 49330
D59: September | E59: 24997
...
